<?xml version="1.0"?>
<sdf version="1.4">
  <model name="Unicycle">
    <!--pose>0 0 0.05 0 0 0</pose-->
    <pose>0.0 0 0.05 0 0 0</pose>
    <link name="carbody">
      <pose>0.0 0 0 0 0 0</pose>
      <inertial>
        <pose>0.15 0 0.1 0 0 0</pose>
        <mass>2.3</mass>
        <!-- will have to do xacro-->
        <inertia>
          <ixx>0.41</ixx>
          <ixy>0</ixy>
          <ixz>0</ixz>
          <iyy>0.416553</iyy>
          <iyz>0</iyz>
          <izz>0.216553</izz>
        </inertia>
      </inertial>
      <collision name="carbody_collision">
        <pose>0.17 0.0 0.055 0.0 0.0 0.0</pose>
        <!--pose>-0.13 0 0 1.5707 5.55112e-17 1.5707</pose-->
        <geometry>
          <box>
            <!--size>0.47 0.19 0.11</size-->
            <size>0.50 0.30 0.11</size>
          </box>
        </geometry>
        <surface>
          <contact>
            <ode/>
          </contact>
          <friction>
            <ode/>
          </friction>
        </surface>
      </collision>
      <!--collision name="carbody_collision_kinect">
        <pose>0.18 -0.07 0.08 -1.5707 -5.55112e-17 1.5707</pose>
        <geometry>
          <mesh>
            <scale>1e-05 1e-05 1e-05</scale>
            <uri>model://rccar/meshes/kinect_sensor.dae</uri>
          </mesh>
        </geometry>
        <surface>
          <contact>
            <ode/>
          </contact>
          <friction>
            <ode/>
          </friction>
        </surface>
      </collision-->
      <visual name="carbody_visual">
        <!--pose>-0.13 0 0 1.5707 5.55112e-17 1.5707</pose-->
        <pose>0.0 0.005 0.0 0.0 0.0 0.0</pose>
        <geometry>
          <mesh>
            <uri>model://rccar/meshes/traxxas1.dae</uri>
          </mesh>
        </geometry>
        <!--material>
          <script>
            <uri>model://polaris_ranger_xp900/materials/scripts</uri>
            <uri>model://polaris_ranger_xp900/materials/textures</uri>
            <name>PolarisXP900/Diffuse</name>
          </script>
        </material-->
        <!--material>
          <script>
            <uri>file://media/materials/scripts/gazebo.material</uri>
            <name>Gazebo/RedGlow</name>
          </script>
        </material-->
      </visual>
      <!--visual name="carbody_visual_kinect">
        <pose>0.18 -0.07 0.08 -1.5707 -5.55112e-17 1.5707</pose>
        <geometry>
          <mesh>
            <scale>1e-05 1e-05 1e-05</scale>
            <uri>model://rccar/meshes/kinect_sensor.dae</uri>
          </mesh>
        </geometry>
      </visual-->
      <!--gravity>1</gravity-->
      <velocity_decay>
        <linear>0</linear>
        <angular>0</angular>
      </velocity_decay>
      <self_collide>0</self_collide>
    </link>
    <link name="backwheels">
      <pose>0 0 0 0 0 0</pose>
      <inertial>
        <pose>0 0 0 0 0 0</pose>
        <mass>0.6</mass>
        <inertia>
          <ixx>0.03014</ixx>
          <ixy>0</ixy>
          <ixz>0</ixz>
          <iyy>0.03014</iyy>
          <iyz>0</iyz>
          <!--izz>0.02</izz-->
          <izz>0.03014</izz>
        </inertia>
      </inertial>
      <collision name="backwheel1_collision">
        <pose>0 -0.13 0 1.570796 0 0</pose>
        <geometry>
          <cylinder>
            <length>0.05</length>
            <radius>0.05</radius>
          </cylinder>
        </geometry>
        <surface>
				  <!--bounce>
						<restitution_coefficient>0.0</restitution_coefficient>
					</bounce-->
          <friction>
            <ode>
              <mu>1.0</mu>
              <mu2>1.0</mu2>
              <fdir1>0 0 1</fdir1>
              <slip1>0.0</slip1>
              <slip2>0.0</slip2>
            </ode>
          </friction>
          <contact>
            <ode>
              <min_depth>0.005</min_depth>
              <kp>1e8</kp>
							<soft_cfm>0.05</soft_cfm>
            </ode>
          </contact>
        </surface>
      </collision>
      <collision name="backwheel2_collision">
        <pose>0 0.13 0 1.570796 0 0</pose>
        <geometry>
          <cylinder>
            <length>0.05</length>
            <radius>0.05</radius>
          </cylinder>
        </geometry>
        <surface>
          <friction>
            <ode>
              <mu>1.0</mu>
              <mu2>1.0</mu2>
              <fdir1>0 0 1</fdir1>
              <slip1>0.0</slip1>
              <slip2>0.0</slip2>
            </ode>
          </friction>
          <contact>
            <ode>
              <min_depth>0.005</min_depth>
              <kp>1e8</kp>
							<soft_cfm>0.05</soft_cfm>
            </ode>
          </contact>
        </surface>
      </collision>
      <visual name="backwheel1_visual">
        <pose>0 -0.13 0 1.570796 0 0</pose>
        <geometry>
          <mesh>
            <scale>1 1 1</scale>
            <uri>model://rccar/meshes/wheel.dae</uri>
          </mesh>
          <!--cylinder>
            <length>0.05</length>
            <radius>0.05</radius>
          </cylinder-->
        </geometry>
        <material>
          <script>
            <name>Gazebo/Black</name>
            <uri>__default__</uri>
          </script>
        </material>
      </visual>
      <visual name="backwheel2_visual">
        <pose>0 0.13 0 1.570796 0 0</pose>
        <geometry>
          <mesh>
            <scale>1 1 1</scale>
            <uri>model://rccar/meshes/wheel.dae</uri>
          </mesh>
          <!--cylinder>
            <length>0.05</length>
            <radius>0.05</radius>
          </cylinder-->
        </geometry>
        <material>
          <script>
            <name>Gazebo/Black</name>
            <uri>__default__</uri>
          </script>
        </material>
      </visual>
      <velocity_decay>
        <linear>0</linear>
        <angular>0</angular>
      </velocity_decay>
      <!--gravity>1</gravity-->
      <velocity_decay>
        <linear>0</linear>
        <angular>0</angular>
      </velocity_decay>
      <self_collide>0</self_collide>
    </link>
    <joint name="base_to_backwheels" type="revolute">
      <child>backwheels</child>
      <parent>carbody</parent>
      <axis>
        <xyz>0 1 0</xyz>
        <dynamics>
          <damping>0.0</damping>
        </dynamics>
      </axis>
    </joint>
    <link name="steeringblock1">
      <pose>0.3 -0.12 0 0 0 0</pose>
      <inertial>
        <pose>0 0 0 0 0 0</pose>
        <mass>0.1 </mass>
        <!-- very less mass-->
        <inertia>
          <ixx> 1e-3 </ixx>
          <ixy>0</ixy>
          <ixz>0</ixz>
          <iyy> 1e-3 </iyy>
          <iyz>0</iyz>
          <izz> 1e-3 </izz>
        </inertia>
      </inertial>
    </link>
    <joint name="base_to_steeringblock1" type="revolute">
      <child>steeringblock1</child>
      <parent>carbody</parent>
      <axis>
        <xyz>0 0 1</xyz>
        <limit>
          <lower>-0.785</lower>
          <upper>0.785</upper>
        </limit>
        <dynamics>
          <damping>0.0</damping>
        </dynamics>
      </axis>
			<physics>
				<ode>
          <!--cfm_damping>1</cfm_damping-->
					<limit>
						<cfm>0.0</cfm>
						<erp>0.5</erp>
					</limit>
				</ode>
			</physics>
    </joint>
    <link name="frontwheel1">
      <pose>0.3 -0.12 0 -1.570796 0 0</pose>
      <inertial>
        <pose>0 0 0 0 0 0</pose>
        <mass>0.3</mass>
        <inertia>
          <ixx>0.01</ixx>
          <ixy>0</ixy>
          <ixz>0</ixz>
          <iyy>0.01</iyy>
          <iyz>0</iyz>
          <izz>0.01</izz>
        </inertia>
      </inertial>
      <collision name="frontwheel1_collision">
        <pose>0 0 0 0 0 0</pose>
        <geometry>
          <cylinder>
            <length>0.05</length>
            <radius>0.05</radius>
          </cylinder>
        </geometry>
        <surface>
          <friction>
            <ode>
              <mu>1.0</mu>
              <mu2>1.0</mu2>
              <fdir1>0 0 1</fdir1>
              <slip1>0.0</slip1>
              <slip2>0.0</slip2>
            </ode>
          </friction>
          <contact>
            <ode>
              <min_depth>0.005</min_depth>
              <kp>1e8</kp>
							<soft_cfm>0.05</soft_cfm>
            </ode>
          </contact>
        </surface>
      </collision>
      <visual name="frontwheel1_visual">
        <pose>0 0 0 0 0 0</pose>
        <geometry>
          <mesh>
            <scale>1 1 1</scale>
            <uri>model://rccar/meshes/wheel.dae</uri>
          </mesh>
          <!---cylinder>
            <length>0.05</length>
            <radius>0.05</radius>
          </cylinder-->
        </geometry>
        <material>
          <script>
            <name>Gazebo/Black</name>
            <uri>__default__</uri>
          </script>
        </material>
      </visual>
      <!--gravity>1</gravity-->
      <velocity_decay>
        <linear>0</linear>
        <angular>0</angular>
      </velocity_decay>
      <self_collide>0</self_collide>
    </link>
    <joint name="steeringblock1_to_frontwheel1" type="revolute">
      <child>frontwheel1</child>
      <parent>steeringblock1</parent>
      <axis>
        <xyz>0 1 0</xyz>
        <dynamics>
          <damping>0.0</damping>
        </dynamics>
      </axis>
    </joint>
    <link name="steeringblock2">
      <pose>0.3 0.12 0 0 0 0</pose>
      <inertial>
        <pose>0 0 0 0 0 0</pose>
        <mass>0.1 </mass>
        <!-- very less mass-->
        <inertia>
          <ixx> 1e-3 </ixx>
          <ixy>0</ixy>
          <ixz>0</ixz>
          <iyy> 1e-3 </iyy>
          <iyz>0</iyz>
          <izz> 1e-3 </izz>
        </inertia>
      </inertial>
    </link>
    <joint name="base_to_steeringblock2" type="revolute">
      <child>steeringblock2</child>
      <parent>carbody</parent>
      <axis>
        <xyz>0 0 1</xyz>
        <limit>
          <lower>-0.785</lower>
          <upper>0.785</upper>
        </limit>
        <dynamics>
          <damping>0.0</damping>
        </dynamics>
      </axis>
			<physics>
        <ode>
          <!--cfm_damping>1</cfm_damping-->
          <limit>
            <cfm>0.000000</cfm>
            <erp>0.500000</erp>
          </limit>
        </ode>
      </physics>
    </joint>
    <link name="frontwheel2">
      <pose>0.3 0.12 0 -1.570796 0 0</pose>
      <inertial>
        <pose>0 0 0 0 -0 0</pose>
        <mass>0.3</mass>
        <inertia>
          <ixx>0.01</ixx>
          <ixy>0</ixy>
          <ixz>0</ixz>
          <iyy>0.01</iyy>
          <iyz>0</iyz>
          <izz>0.01</izz>
        </inertia>
      </inertial>
      <collision name="frontwheel2_collision">
        <pose>0 0 0 0 0 0</pose>
        <geometry>
          <cylinder>
            <length>0.05</length>
            <radius>0.05</radius>
          </cylinder>
        </geometry>
        <!--max_contacts>1</max_contacts-->
        <surface>
          <friction>
            <ode>
              <mu>1.0</mu>
              <mu2>1.0</mu2>
              <fdir1>0 0 1</fdir1>
              <slip1>0.0</slip1>
              <slip2>0.0</slip2>
            </ode>
          </friction>
          <contact>
            <ode>
              <min_depth>0.005</min_depth>
              <kp>1e8</kp>
							<soft_cfm>0.05</soft_cfm>
            </ode>
          </contact>
        </surface>
      </collision>
      <visual name="frontwheel2_visual">
        <pose>0 0 0 0 -0 0</pose>
        <geometry>
          <mesh>
            <scale>1 1 1</scale>
            <uri>model://rccar/meshes/wheel.dae</uri>
          </mesh>
          <!--cylinder>
            <length>0.05</length>
            <radius>0.05</radius>
          </cylinder-->
        </geometry>
        <material>
          <script>
            <name>Gazebo/Black</name>
            <uri>__default__</uri>
          </script>
        </material>
      </visual>
      <!--gravity>1</gravity-->
      <velocity_decay>
        <linear>0</linear>
        <angular>0</angular>
      </velocity_decay>
      <self_collide>0</self_collide>
    </link>
    <joint name="steeringblock2_to_frontwheel2" type="revolute">
      <child>frontwheel2</child>
      <parent>steeringblock2</parent>
      <axis>
        <xyz>0 1 0</xyz>
        <dynamics>
          <damping>0.0</damping>
        </dynamics>
      </axis>
    </joint>
  </model>
</sdf>
